Started
======== Running on http://127.0.0.1:8082 ========
(Press CTRL+C to quit)
Started
unhandled exception during asyncio.run() shutdown
task: <Task finished name='Task-1' coro=<_run_app() done, defined at /home/wizard/PycharmProjects/demoStorage/venv/lib/python3.8/site-packages/aiohttp/web.py:287> exception=OSError(98, "error while attempting to bind on address ('127.0.0.1', 8082): address already in use")>
Traceback (most recent call last):
  File "/home/wizard/PycharmProjects/demoStorage/venv/lib/python3.8/site-packages/aiohttp/web.py", line 508, in run_app
    loop.run_until_complete(main_task)
  File "/usr/lib/python3.8/asyncio/base_events.py", line 616, in run_until_complete
    return future.result()
  File "/home/wizard/PycharmProjects/demoStorage/venv/lib/python3.8/site-packages/aiohttp/web.py", line 411, in _run_app
    await site.start()
  File "/home/wizard/PycharmProjects/demoStorage/venv/lib/python3.8/site-packages/aiohttp/web_runner.py", line 121, in start
    self._server = await loop.create_server(
  File "/usr/lib/python3.8/asyncio/base_events.py", line 1463, in create_server
    raise OSError(err.errno, 'error while attempting '
OSError: [Errno 98] error while attempting to bind on address ('127.0.0.1', 8082): address already in use
Traceback (most recent call last):
  File "dataStoraged.py", line 243, in <module>
    server_daemon.start()
  File "dataStoraged.py", line 150, in start
    self.run(*args, **kwargs)
  File "dataStoraged.py", line 225, in run
    run_app(host=host, port=port)
  File "/home/wizard/PycharmProjects/datastorage/server.py", line 136, in run_app
    web.run_app(app, host=HOST, port=PORT)
  File "/home/wizard/PycharmProjects/demoStorage/venv/lib/python3.8/site-packages/aiohttp/web.py", line 508, in run_app
    loop.run_until_complete(main_task)
  File "/usr/lib/python3.8/asyncio/base_events.py", line 616, in run_until_complete
    return future.result()
  File "/home/wizard/PycharmProjects/demoStorage/venv/lib/python3.8/site-packages/aiohttp/web.py", line 411, in _run_app
    await site.start()
  File "/home/wizard/PycharmProjects/demoStorage/venv/lib/python3.8/site-packages/aiohttp/web_runner.py", line 121, in start
    self._server = await loop.create_server(
  File "/usr/lib/python3.8/asyncio/base_events.py", line 1463, in create_server
    raise OSError(err.errno, 'error while attempting '
OSError: [Errno 98] error while attempting to bind on address ('127.0.0.1', 8082): address already in use
Started
unhandled exception during asyncio.run() shutdown
task: <Task finished name='Task-1' coro=<_run_app() done, defined at /home/wizard/PycharmProjects/demoStorage/venv/lib/python3.8/site-packages/aiohttp/web.py:287> exception=OSError(98, "error while attempting to bind on address ('127.0.0.1', 8082): address already in use")>
Traceback (most recent call last):
  File "/home/wizard/PycharmProjects/demoStorage/venv/lib/python3.8/site-packages/aiohttp/web.py", line 508, in run_app
    loop.run_until_complete(main_task)
  File "/usr/lib/python3.8/asyncio/base_events.py", line 616, in run_until_complete
    return future.result()
  File "/home/wizard/PycharmProjects/demoStorage/venv/lib/python3.8/site-packages/aiohttp/web.py", line 411, in _run_app
    await site.start()
  File "/home/wizard/PycharmProjects/demoStorage/venv/lib/python3.8/site-packages/aiohttp/web_runner.py", line 121, in start
    self._server = await loop.create_server(
  File "/usr/lib/python3.8/asyncio/base_events.py", line 1463, in create_server
    raise OSError(err.errno, 'error while attempting '
OSError: [Errno 98] error while attempting to bind on address ('127.0.0.1', 8082): address already in use
Traceback (most recent call last):
  File "dataStoraged.py", line 243, in <module>
    server_daemon.start()
  File "dataStoraged.py", line 150, in start
    self.run(*args, **kwargs)
  File "dataStoraged.py", line 225, in run
    run_app(host=host, port=port)
  File "/home/wizard/PycharmProjects/datastorage/server.py", line 136, in run_app
    web.run_app(app, host=HOST, port=PORT)
  File "/home/wizard/PycharmProjects/demoStorage/venv/lib/python3.8/site-packages/aiohttp/web.py", line 508, in run_app
    loop.run_until_complete(main_task)
  File "/usr/lib/python3.8/asyncio/base_events.py", line 616, in run_until_complete
    return future.result()
  File "/home/wizard/PycharmProjects/demoStorage/venv/lib/python3.8/site-packages/aiohttp/web.py", line 411, in _run_app
    await site.start()
  File "/home/wizard/PycharmProjects/demoStorage/venv/lib/python3.8/site-packages/aiohttp/web_runner.py", line 121, in start
    self._server = await loop.create_server(
  File "/usr/lib/python3.8/asyncio/base_events.py", line 1463, in create_server
    raise OSError(err.errno, 'error while attempting '
OSError: [Errno 98] error while attempting to bind on address ('127.0.0.1', 8082): address already in use
Started
unhandled exception during asyncio.run() shutdown
task: <Task finished name='Task-1' coro=<_run_app() done, defined at /home/wizard/PycharmProjects/demoStorage/venv/lib/python3.8/site-packages/aiohttp/web.py:287> exception=OSError(98, "error while attempting to bind on address ('127.0.0.1', 8082): address already in use")>
Traceback (most recent call last):
  File "/home/wizard/PycharmProjects/demoStorage/venv/lib/python3.8/site-packages/aiohttp/web.py", line 508, in run_app
    loop.run_until_complete(main_task)
  File "/usr/lib/python3.8/asyncio/base_events.py", line 616, in run_until_complete
    return future.result()
  File "/home/wizard/PycharmProjects/demoStorage/venv/lib/python3.8/site-packages/aiohttp/web.py", line 411, in _run_app
    await site.start()
  File "/home/wizard/PycharmProjects/demoStorage/venv/lib/python3.8/site-packages/aiohttp/web_runner.py", line 121, in start
    self._server = await loop.create_server(
  File "/usr/lib/python3.8/asyncio/base_events.py", line 1463, in create_server
    raise OSError(err.errno, 'error while attempting '
OSError: [Errno 98] error while attempting to bind on address ('127.0.0.1', 8082): address already in use
Traceback (most recent call last):
  File "dataStoraged.py", line 243, in <module>
    server_daemon.start()
  File "dataStoraged.py", line 150, in start
    self.run(*args, **kwargs)
  File "dataStoraged.py", line 225, in run
    run_app(host=host, port=port)
  File "/home/wizard/PycharmProjects/datastorage/server.py", line 136, in run_app
    web.run_app(app, host=HOST, port=PORT)
  File "/home/wizard/PycharmProjects/demoStorage/venv/lib/python3.8/site-packages/aiohttp/web.py", line 508, in run_app
    loop.run_until_complete(main_task)
  File "/usr/lib/python3.8/asyncio/base_events.py", line 616, in run_until_complete
    return future.result()
  File "/home/wizard/PycharmProjects/demoStorage/venv/lib/python3.8/site-packages/aiohttp/web.py", line 411, in _run_app
    await site.start()
  File "/home/wizard/PycharmProjects/demoStorage/venv/lib/python3.8/site-packages/aiohttp/web_runner.py", line 121, in start
    self._server = await loop.create_server(
  File "/usr/lib/python3.8/asyncio/base_events.py", line 1463, in create_server
    raise OSError(err.errno, 'error while attempting '
OSError: [Errno 98] error while attempting to bind on address ('127.0.0.1', 8082): address already in use
Started
unhandled exception during asyncio.run() shutdown
task: <Task finished name='Task-1' coro=<_run_app() done, defined at /home/wizard/PycharmProjects/demoStorage/venv/lib/python3.8/site-packages/aiohttp/web.py:287> exception=OSError(98, "error while attempting to bind on address ('127.0.0.1', 8082): address already in use")>
Traceback (most recent call last):
  File "/home/wizard/PycharmProjects/demoStorage/venv/lib/python3.8/site-packages/aiohttp/web.py", line 508, in run_app
    loop.run_until_complete(main_task)
  File "/usr/lib/python3.8/asyncio/base_events.py", line 616, in run_until_complete
    return future.result()
  File "/home/wizard/PycharmProjects/demoStorage/venv/lib/python3.8/site-packages/aiohttp/web.py", line 411, in _run_app
    await site.start()
  File "/home/wizard/PycharmProjects/demoStorage/venv/lib/python3.8/site-packages/aiohttp/web_runner.py", line 121, in start
    self._server = await loop.create_server(
  File "/usr/lib/python3.8/asyncio/base_events.py", line 1463, in create_server
    raise OSError(err.errno, 'error while attempting '
OSError: [Errno 98] error while attempting to bind on address ('127.0.0.1', 8082): address already in use
Traceback (most recent call last):
  File "/home/wizard/PycharmProjects/demoStorage/venv/lib/python3.8/site-packages/aiohttp/web.py", line 508, in run_app
    loop.run_until_complete(main_task)
  File "/usr/lib/python3.8/asyncio/base_events.py", line 616, in run_until_complete
    return future.result()
  File "/home/wizard/PycharmProjects/demoStorage/venv/lib/python3.8/site-packages/aiohttp/web.py", line 411, in _run_app
    await site.start()
  File "/home/wizard/PycharmProjects/demoStorage/venv/lib/python3.8/site-packages/aiohttp/web_runner.py", line 121, in start
    self._server = await loop.create_server(
  File "/usr/lib/python3.8/asyncio/base_events.py", line 1463, in create_server
    raise OSError(err.errno, 'error while attempting '
OSError: [Errno 98] error while attempting to bind on address ('127.0.0.1', 8082): address already in use
Started
======== Running on http://127.0.0.1:8082 ========
(Press CTRL+C to quit)
Traceback (most recent call last):
  File "/home/wizard/PycharmProjects/demoStorage/venv/lib/python3.8/site-packages/aiohttp/web.py", line 489, in run_app
    main_task = loop.create_task(
  File "/usr/lib/python3.8/asyncio/base_events.py", line 429, in create_task
    self._check_closed()
  File "/usr/lib/python3.8/asyncio/base_events.py", line 508, in _check_closed
    raise RuntimeError('Event loop is closed')
RuntimeError: Event loop is closed

During handling of the above exception, another exception occurred:

Traceback (most recent call last):
  File "/snap/pycharm-community/222/plugins/python-ce/helpers/pydev/pydevd.py", line 1477, in _exec
    pydev_imports.execfile(file, globals, locals)  # execute the script
  File "/snap/pycharm-community/222/plugins/python-ce/helpers/pydev/_pydev_imps/_pydev_execfile.py", line 18, in execfile
    exec(compile(contents+"\n", file, 'exec'), glob, loc)
  File "/home/wizard/PycharmProjects/datastorage/dataStoraged.py", line 244, in <module>
    
  File "/home/wizard/PycharmProjects/datastorage/dataStoraged.py", line 225, in run
    run_app(host=host, port=port)
  File "/home/wizard/PycharmProjects/datastorage/server.py", line 136, in run_app
    web.run_app(app, host=HOST, port=PORT)
  File "/home/wizard/PycharmProjects/demoStorage/venv/lib/python3.8/site-packages/aiohttp/web.py", line 512, in run_app
    _cancel_tasks({main_task}, loop)
UnboundLocalError: local variable 'main_task' referenced before assignment
Started
======== Running on http://127.0.0.1:8080 ========
(Press CTRL+C to quit)
Error handling request
Traceback (most recent call last):
  File "/home/wizard/PycharmProjects/demoStorage/venv/lib/python3.8/site-packages/aiohttp/web_protocol.py", line 314, in data_received
    messages, upgraded, tail = self._request_parser.feed_data(data)
  File "aiohttp/_http_parser.pyx", line 546, in aiohttp._http_parser.HttpParser.feed_data
aiohttp.http_exceptions.BadStatusLine: 400, message="Bad status line 'invalid HTTP method'"
Error handling request
Traceback (most recent call last):
  File "/home/wizard/PycharmProjects/demoStorage/venv/lib/python3.8/site-packages/aiohttp/web_protocol.py", line 314, in data_received
    messages, upgraded, tail = self._request_parser.feed_data(data)
  File "aiohttp/_http_parser.pyx", line 546, in aiohttp._http_parser.HttpParser.feed_data
aiohttp.http_exceptions.BadStatusLine: 400, message="Bad status line 'invalid HTTP method'"
Error handling request
Traceback (most recent call last):
  File "/home/wizard/PycharmProjects/demoStorage/venv/lib/python3.8/site-packages/aiohttp/web_protocol.py", line 314, in data_received
    messages, upgraded, tail = self._request_parser.feed_data(data)
  File "aiohttp/_http_parser.pyx", line 546, in aiohttp._http_parser.HttpParser.feed_data
aiohttp.http_exceptions.BadStatusLine: 400, message="Bad status line 'invalid HTTP method'"
Error handling request
Traceback (most recent call last):
  File "/home/wizard/PycharmProjects/demoStorage/venv/lib/python3.8/site-packages/aiohttp/web_protocol.py", line 314, in data_received
    messages, upgraded, tail = self._request_parser.feed_data(data)
  File "aiohttp/_http_parser.pyx", line 546, in aiohttp._http_parser.HttpParser.feed_data
aiohttp.http_exceptions.BadStatusLine: 400, message="Bad status line 'invalid HTTP method'"
Error handling request
Traceback (most recent call last):
  File "/home/wizard/PycharmProjects/demoStorage/venv/lib/python3.8/site-packages/aiohttp/web_protocol.py", line 314, in data_received
    messages, upgraded, tail = self._request_parser.feed_data(data)
  File "aiohttp/_http_parser.pyx", line 546, in aiohttp._http_parser.HttpParser.feed_data
aiohttp.http_exceptions.BadStatusLine: 400, message="Bad status line 'invalid HTTP method'"
Error handling request
Traceback (most recent call last):
  File "/home/wizard/PycharmProjects/demoStorage/venv/lib/python3.8/site-packages/aiohttp/web_protocol.py", line 314, in data_received
    messages, upgraded, tail = self._request_parser.feed_data(data)
  File "aiohttp/_http_parser.pyx", line 546, in aiohttp._http_parser.HttpParser.feed_data
aiohttp.http_exceptions.BadStatusLine: 400, message="Bad status line 'invalid HTTP method'"
Error handling request
Traceback (most recent call last):
  File "/home/wizard/PycharmProjects/demoStorage/venv/lib/python3.8/site-packages/aiohttp/web_protocol.py", line 314, in data_received
    messages, upgraded, tail = self._request_parser.feed_data(data)
  File "aiohttp/_http_parser.pyx", line 546, in aiohttp._http_parser.HttpParser.feed_data
aiohttp.http_exceptions.BadStatusLine: 400, message="Bad status line 'invalid HTTP method'"
Error handling request
Traceback (most recent call last):
  File "/home/wizard/PycharmProjects/demoStorage/venv/lib/python3.8/site-packages/aiohttp/web_protocol.py", line 314, in data_received
    messages, upgraded, tail = self._request_parser.feed_data(data)
  File "aiohttp/_http_parser.pyx", line 546, in aiohttp._http_parser.HttpParser.feed_data
aiohttp.http_exceptions.BadStatusLine: 400, message="Bad status line 'invalid HTTP method'"
Started
======== Running on http://127.0.0.1:8080 ========
(Press CTRL+C to quit)
Error handling request
Traceback (most recent call last):
  File "/home/wizard/PycharmProjects/demoStorage/venv/lib/python3.8/site-packages/aiohttp/web_protocol.py", line 422, in _handle_request
    resp = await self._request_handler(request)
  File "/home/wizard/PycharmProjects/demoStorage/venv/lib/python3.8/site-packages/aiohttp/web_app.py", line 499, in _handle
    resp = await handler(request)
  File "/home/wizard/PycharmProjects/datastorage/server.py", line 164, in get_structure_info
    serialized_storage = serialize_folder(storage_path)
  File "/home/wizard/PycharmProjects/datastorage/server.py", line 154, in serialize_folder
    folder_serialized.update({"children": folder_serialized["children"] + data})
TypeError: can only concatenate list (not "dict") to list
Error handling request
Traceback (most recent call last):
  File "/home/wizard/PycharmProjects/demoStorage/venv/lib/python3.8/site-packages/aiohttp/web_protocol.py", line 422, in _handle_request
    resp = await self._request_handler(request)
  File "/home/wizard/PycharmProjects/demoStorage/venv/lib/python3.8/site-packages/aiohttp/web_app.py", line 499, in _handle
    resp = await handler(request)
  File "/home/wizard/PycharmProjects/datastorage/server.py", line 164, in get_structure_info
    serialized_storage = serialize_folder(storage_path)
  File "/home/wizard/PycharmProjects/datastorage/server.py", line 154, in serialize_folder
    folder_serialized.update({"children": folder_serialized["children"] + data})
TypeError: can only concatenate list (not "dict") to list
Error handling request
Traceback (most recent call last):
  File "/home/wizard/PycharmProjects/demoStorage/venv/lib/python3.8/site-packages/aiohttp/web_protocol.py", line 422, in _handle_request
    resp = await self._request_handler(request)
  File "/home/wizard/PycharmProjects/demoStorage/venv/lib/python3.8/site-packages/aiohttp/web_app.py", line 499, in _handle
    resp = await handler(request)
  File "/home/wizard/PycharmProjects/datastorage/server.py", line 164, in get_structure_info
    serialized_storage = serialize_folder(storage_path)
  File "/home/wizard/PycharmProjects/datastorage/server.py", line 154, in serialize_folder
    folder_serialized.update({"children": folder_serialized["children"] + data})
TypeError: can only concatenate list (not "dict") to list
Started
======== Running on http://127.0.0.1:8080 ========
(Press CTRL+C to quit)
Error handling request
Traceback (most recent call last):
  File "/home/wizard/PycharmProjects/demoStorage/venv/lib/python3.8/site-packages/aiohttp/web_protocol.py", line 422, in _handle_request
    resp = await self._request_handler(request)
  File "/home/wizard/PycharmProjects/demoStorage/venv/lib/python3.8/site-packages/aiohttp/web_app.py", line 499, in _handle
    resp = await handler(request)
  File "/home/wizard/PycharmProjects/datastorage/server.py", line 164, in get_structure_info
    serialized_storage = serialize_folder(storage_path)
  File "/home/wizard/PycharmProjects/datastorage/server.py", line 154, in serialize_folder
    folder_serialized.update({"children": folder_serialized["children"] + data})
TypeError: can only concatenate list (not "dict") to list
Started
======== Running on http://127.0.0.1:8080 ========
(Press CTRL+C to quit)
Started
======== Running on http://127.0.0.1:8080 ========
(Press CTRL+C to quit)
Started
unhandled exception during asyncio.run() shutdown
task: <Task finished name='Task-1' coro=<_run_app() done, defined at /home/wizard/PycharmProjects/demoStorage/venv/lib/python3.8/site-packages/aiohttp/web.py:287> exception=OSError(98, "error while attempting to bind on address ('127.0.0.1', 8080): address already in use")>
Traceback (most recent call last):
  File "/home/wizard/PycharmProjects/demoStorage/venv/lib/python3.8/site-packages/aiohttp/web.py", line 508, in run_app
    loop.run_until_complete(main_task)
  File "/usr/lib/python3.8/asyncio/base_events.py", line 616, in run_until_complete
    return future.result()
  File "/home/wizard/PycharmProjects/demoStorage/venv/lib/python3.8/site-packages/aiohttp/web.py", line 411, in _run_app
    await site.start()
  File "/home/wizard/PycharmProjects/demoStorage/venv/lib/python3.8/site-packages/aiohttp/web_runner.py", line 121, in start
    self._server = await loop.create_server(
  File "/usr/lib/python3.8/asyncio/base_events.py", line 1463, in create_server
    raise OSError(err.errno, 'error while attempting '
OSError: [Errno 98] error while attempting to bind on address ('127.0.0.1', 8080): address already in use
Traceback (most recent call last):
  File "/home/wizard/PycharmProjects/datastorage/dataStoraged.py", line 243, in <module>
    server_daemon.start(host=parsed.host, port=parsed.port)
  File "/home/wizard/PycharmProjects/datastorage/dataStoraged.py", line 150, in start
    self.run(*args, **kwargs)
  File "/home/wizard/PycharmProjects/datastorage/dataStoraged.py", line 225, in run
    run_app(host=host, port=port)
  File "/home/wizard/PycharmProjects/datastorage/server.py", line 206, in run_app
    web.run_app(app, host=HOST, port=PORT)
  File "/home/wizard/PycharmProjects/demoStorage/venv/lib/python3.8/site-packages/aiohttp/web.py", line 508, in run_app
    loop.run_until_complete(main_task)
  File "/usr/lib/python3.8/asyncio/base_events.py", line 616, in run_until_complete
    return future.result()
  File "/home/wizard/PycharmProjects/demoStorage/venv/lib/python3.8/site-packages/aiohttp/web.py", line 411, in _run_app
    await site.start()
  File "/home/wizard/PycharmProjects/demoStorage/venv/lib/python3.8/site-packages/aiohttp/web_runner.py", line 121, in start
    self._server = await loop.create_server(
  File "/usr/lib/python3.8/asyncio/base_events.py", line 1463, in create_server
    raise OSError(err.errno, 'error while attempting '
OSError: [Errno 98] error while attempting to bind on address ('127.0.0.1', 8080): address already in use
Started
======== Running on http://127.0.0.1:8080 ========
(Press CTRL+C to quit)
